Workbook

Sheet Head
A1: NIK AMG | E1: NIK DAM
A2: 119000001 | B2: Herman Suwanto | C2: Manufacturing Head | E2: 128000005 | F2: Sartono
A3: 119000004 | B3: Angela Stephanie | C3: QC and R&D Deputy Manager | E3: 128000006 | F3: Agnes Vivi Cahyani
A4: 119000010 | B4: Nathan Wilman | C4: Accounting Chief SPV 2 | E4: 128000007 | F4: Stevanus Cahya Pratama
A5: 119000138 | B5: Agnes Vivi Cahyani | C5: HRD & GA Deputy Manager | E5: 128000008 | F5: Natalia Gunawan
A6: 119000223 | B6: Margaret Emmanuel K | C6: HRD & GA Deputy Manager | E6: 128000009 | F6: Angela stephanie
A7: 119000162 | B7: Stevanus Cahya Pratama | C7: Manager ACC | E7: 128000045 | F7: NATHANIA HARTONO
A8: 119000029 | B8: Sartono | C8: Logistic Deputy Manager | E8: 128000046 | F8: NATHAN WILMAN
A9: 119000078 | B9: Nathania Hartono | C9: Supervisor Purchasing | E9: 128000047 | F9: Joan Imanuela
A10: 119000082 | B10: Joan Imanuela | C10: Supervisor Material Plan & Raw Material | E10: 128000050 | F10: Herman Suwanto
E11: 128000085 | F11: Margaret Emmanuel K

Sheet CONFIG_MODUL
A1: S | B1: LINK_MODUL
A2: GATE_PABRIK | B2: https://script.google.com/macros/s/AKfycbyjQ36Nlastyw1xBgzvojgX6QH2oPxB6462YKg0sELBb3gb08dYQuKHz5X_RLFntfoV9g/exec
A3: AREA_KERJA | B3: https://script.google.com/macros/s/AKfycbyu6uW7XgdZPtJysgtf3x0i3E7cxR5Hrb_dZNKYns0QJ6Lef7xzbC0mT3uP_rREHz5ypA/exec
A4: REPORT | B4: https://script.google.com/macros/s/AKfycbycdcUt4y9RdoQIOTnIzWs6AxyZe5JayFhbk6f9abnv5kr3VAWapXicdVvRGn3o53BS/exec
A5: HOME_PORTAL | B5: https://script.google.com/macros/s/AKfycbzVN4Z58pluVPnUG1jBOBc4hLggJjDAlrSekiW9DtkHqvk8rEsSKuhvhWHTbsHbaP8m/exec

Sheet JADWAL_SHIFT
A1: NIK | B1: NAMA | C1: DEPT | D1: SHIFT | E1: TANGGAL_MULAI | F1: TANGGAL_SELESAI

Sheet KARYAWAN
A1: NIK | B1: NAMA | C1: TYPE KAYARAWAN | D1: DEPT | E1: JABATAN | F1: USER LEVEL | G1: PASSWORD
A2: 128000001 | B2: Iman Nurchaedi S. | C2: STAFF | D2: PROD | E2: Plant Manager | F2: ADMINISTRATOR | G2: ADM0912
A3: 128000003 | B3: Andre Santosa | C3: STAFF | D3: ENG | E3: Engineering Deputy Manager | F3: ADMINISTRATOR | G3: ADM0912
A4: 128000010 | B4: Dendy Saputra | C4: STAFF | D4: PROD | E4: Line Leader | F4: PENGAWAS | G4: PGW0912
A5: 128000012 | B5: Evita | C5: STAFF | D5: PROD | E5: Production Chief SPV 1 | F5: ADMINISTRATOR | G5: ADM0912
A6: 128000013 | B6: Aminulloh | C6: STAFF | D6: LOG | E6: Staff Warehouse Sparepart | F6: PENGAWAS | G6: PGW0912
A7: 128000017 | B7: Sandi Iswanto | C7: STAFF | D7: QRD | E7: Staff Quality Control Production | F7: PENGAWAS | G7: PGW0912
A8: 128000019 | B8: Yeni Ferianto | C8: STAFF | D8: QRD | E8: Staff Quality Control Production | F8: PENGAWAS | G8: PGW0912
A9: 128000020 | B9: Adeliana Dewi Putri Salihah | C9: STAFF | D9: HRGA | E9: Sr. Staff Talent Acquisition | F9: PENGAWAS | G9: PGW0912
A10: 128000022 | B10: Hendra Setiawan | C10: STAFF | D10: PROD | E10: Production Engineer | F10: PENGAWAS | G10: PGW0912
A11: 128000023 | B11: Iman Muaimin | C11: STAFF | D11: LOG | E11: Sr. Staff Warehouse Raw Material | F11: PENGAWAS | G11: PGW0912
A12: 128000024 | B12: Taufik Faturochman | C12: STAFF | D12: LOG | E12: Warehouse Supervisor | F12: ADMINISTRATOR | G12: ADM0912
A13: 128000027 | B13: Gembong Hagung Harsanto | C13: STAFF | D13: ENG | E13: Engineering Chief Spv 1 | F13: ADMINISTRATOR | G13: ADM0912
... A70: 128000123 | B70: Ivan Jovian | C70: STAFF | D70: ENG | E70: Staff ITE | F70: PENGAWAS | G70: PGW0912
A71: 328000001 | B71: RIO GUSTIAWAN | C71: NON STAFF | D71: ENG | E71: ELECTRICAL MAINTENANCE | F71: KARYAWAN
A72: 328000005 | B72: IRGI FAUZI | C72: NON STAFF | D72: ENG | E72: TECHNICIAN | F72: KARYAWAN
A73: 328000006 | B73: RIZKI | C73: NON STAFF | D73: ENG | E73: TECHNICIAN | F73: KARYAWAN
A74: 328000009 | B74: REZZA FEBRIANA | C74: NON STAFF | D74: ENG | E74: TECHNICIAN | F74: KARYAWAN
A75: 328000010 | B75: DIAZ GHERY JUNIARSYAH RAHMAN | C75: NON STAFF | D75: ENG | E75: TECHNICIAN | F75: KARYAWAN
A76: 328000011 | B76: DENI KUSNADI | C76: NON STAFF | D76: LOG | E76: ADMIN WSP | F76: KARYAWAN
A77: 328000022 | B77: AZHAR AIZAD ALFARIDZI | C77: NON STAFF | D77: PROD | E77: OPERATOR | F77: KARYAWAN
A78: 328000023 | B78: KEPIN NUGRAHA | C78: NON STAFF | D78: PROD | E78: OPERATOR | F78: KARYAWAN
A79: 328000026 | B79: DEDE WAHYUDIN | C79: NON STAFF | D79: PROD | E79: OPERATOR | F79: KARYAWAN
A80: 328000027 | B80: GIGIN GINANJAR | C80: NON STAFF | D80: PROD | E80: OPERATOR | F80: KARYAWAN
A81: 328000028 | B81: TISNA GINANJAR | C81: NON STAFF | D81: PROD | E81: OPERATOR | F81: KARYAWAN
A82: 328000030 | B82: DAVA PUTRA YUDIANSYAH | C82: NON STAFF | D82: PROD | E82: OPERATOR | F82: KARYAWAN
... A520: 328000713 | B520: IRWAN CHRISTIANTO HUTAGALUNG | C520: NON STAFF | D520: PROD | E520: OPERATOR PRODUKSI | F520: KARYAWAN
A521: 428000004 | B521: ADI MUZAKI | C521: Mitra Kerja | D521: HRGA | E521: GA Vendor | F521: SECURITY | G521: SEC0912
A522: 428000006 | B522: BAGAS JUAN PRATAMA | C522: Mitra Kerja | D522: HRGA | E522: GA Vendor | F522: SECURITY | G522: SEC0912
A523: 428000011 | B523: DINO DRAJAT | C523: Mitra Kerja | D523: HRGA | E523: GA Vendor | F523: SECURITY | G523: SEC0912
A524: 428000012 | B524: RIDKI MAULANA | C524: Mitra Kerja | D524: HRGA | E524: GA Vendor | F524: SECURITY | G524: SEC0912
A525: 428000014 | B525: ADITYA SAPUTRA | C525: Mitra Kerja | D525: HRGA | E525: GA Vendor | F525: SECURITY | G525: SEC0912
A526: 428000015 | B526: MOCHAMMAD AJAR NURJI | C526: Mitra Kerja | D526: HRGA | E526: GA Vendor | F526: SECURITY | G526: SEC0912
A527: 428000020 | B527: MUSLIM | C527: Mitra Kerja | D527: HRGA | E527: GA Vendor | F527: SECURITY | G527: SEC0912
A528: 428000021 | B528: CARI IRAWAN | C528: Mitra Kerja | D528: HRGA | E528: GA Vendor | F528: SECURITY | G528: SEC0912
A529: 428000024 | B529: ADI MAULANA | C529: Mitra Kerja | D529: HRGA | E529: GA Vendor | F529: SECURITY | G529: SEC0912
A530: 428000030 | B530: ERDI HERDIANSYAH | C530: Mitra Kerja | D530: HRGA | E530: GA Vendor | F530: SECURITY | G530: SEC0912
A531: 428000031 | B531: SARIP HIDAYAT | C531: Mitra Kerja | D531: HRGA | E531: GA Vendor | F531: SECURITY | G531: SEC0912
A532: 428000032 | B532: HERI HOERUDIN | C532: Mitra Kerja | D532: HRGA | E532: GA Vendor | F532: SECURITY | G532: SEC0912
... A578: 428000095 | B578: Muhamad Lutfi Fathir | C578: Mitra Kerja | D578: HRGA | E578: GA Vendor | F578: SECURITY | G578: SEC0912
...

Sheet Sheet4
D1: =IMAGE("https://barcode.tec-it.com/barcode.ashx?data=" & A7 & "&code=Code128")
A6: MK00160 | H6: =IMAGE("https://barcode.tec-it.com/barcode.ashx?data=" & A6 & "&code=Code128")
A7: MK00171 | D7: =IMAGE("https://barcode.tec-it.com/barcode.ashx?data=" & A7 & "&code=Code128")
A8: MK0090 | B8: =IMAGE("https://barcode.tec-it.com/barcode.ashx?data=" & A8 & "&code=Code128")

Sheet BINDING_KARTU_MK
A1: NO_KARTU_MK | B1: NIK | C1: NAMA | D1: DEPT | E1: JABATAN | F1: WAKTU_BIND | G1: STATUS | H1: WAKTU_RELEASE
A2: MK0090 | B2: 528000069 | C2: Jajang Ardiansyah | D2: PROD | E2: Produksi Harian | F2: 46164.853 | G2: FREE | H2: 46164.855
A3: MK00160 | B3: 628000039 | C3: Nani Maryani | D3: PROD | E3: Produksi Borongan | F3: 46166.99 | G3: FREE | H3: 46186.958
A4: MK00112 | B4: 528000016 | C4: Randi Apriyanto | D4: LOG | E4: WRM Harian | F4: 46171.009 | G4: FREE | H4: 46171.012
A5: MK00112 | B5: 528000059 | C5: N. Santika Dewi | D5: PROD | E5: Produksi Harian | F5: 46171.023 | G5: FREE | H5: 46171.024
A6: MK00126 | B6: 528000052 | C6: Mustopa | D6: PROD | E6: Produksi Harian | F6: 46171.026 | G6: FREE | H6: 46171.027
A7: MK00112 | B7: 528000059 | C7: N. Santika Dewi | D7: PROD | E7: Produksi Harian | F7: 46171.042 | G7: FREE | H7: 46087.58
A8: CK0093 | B8: 528000055 | C8: Dika Prasetya | D8: LOG | E8: WRM Harian | F8: 46171.25 | G8: FREE | H8: 46087.581
A9: MK00156 | B9: 528000201 | C9: Zahwa Amelia Choerunissa | D9: PROD | E9: Produksi Harian | F9: 46171.315 | G9: FREE | H9: 46028.242
A10: MK00184 | B10: 528000099 | C10: Siti Nurawaliah | D10: PROD | E10: Produksi Harian | F10: 46171.317 | G10: FREE | H10: 46059.235
A11: MK00116 | B11: 528000244 | C11: Rodian Rifai | D11: PROD | E11: Produksi Harian | F11: 46171.32 | G11: FREE | H11: 46171.673
A12: MK00181 | B12: 528000286 | C12: Imelda Amelia | D12: PROD | E12: Produksi Harian | F12: 46171.325 | G12: FREE | H12: 46172.012
A13: MK00118 | B13: 528000228 | C13: Banyu Resmi Putri | D13: PROD | E13: Produksi Harian | F13: 46171.329 | G13: FREE | H13: 46059.335
... A66: MK00150 | B66: 528000305 | C66: Puji Puspita | D66: PROD | E66: Produksi Harian | F66: 46028.239 | G66: FREE | H66: 46028.589
A67: 7200181 | B67: 528000251 | C67: Salya Nugraha | D67: PROD | E67: Produksi Harian | F67: 46028.24 | G67: FREE | H67: 46198.831
A68: MK00145 | B68: 528000302 | C68: Henkey gumilar | D68: PROD | E68: Produksi Harian | F68: 46028.243 | G68: FREE | H68: 46028.591
A69: MK00156 | B69: 528000270 | C69: Febri Najmudin | D69: LOG | E69: WRM Harian | F69: 46028.243 | G69: FREE | H69: 46028.588
A70: MK00109 | B70: 528000298 | C70: Desta Cahaya Pratama | D70: PROD | E70: Produksi Harian | F70: 46028.244 | G70: FREE | H70: 46028.588
A71: MK00154 | B71: 528000265 | C71: Muhammad Haerul Rozikin | D71: LOG | E71: WRM Harian | F71: 46028.321 | G71: FREE | H71: 46028.67
A72: MK00138 | B72: 528000296 | C72: Nurdin | D72: PROD | E72: Produksi Harian | F72: 46028.335 | G72: FREE | H72: 46087.575
A73: MK00126 | B73: 528000069 | C73: Jajang Ardiansyah | D73: PROD | E73: Produksi Harian | F73: 46028.335 | G73: FREE | H73: 46028.815
A74: MK00151 | B74: 528000279 | C74: Mahdalena Dalfa Riani | D74: PROD | E74: Produksi Harian | F74: 46028.574 | G74: FREE | H74: 46118.249
A75: MK00116 | B75: 528000297 | C75: Muhamad Budiana | D75: PROD | E75: Produksi Harian | F75: 46028.576 | G75: FREE | H75: 46028.921
A76: MK00148 | B76: 528000300 | C76: Lia pitaloka | D76: PROD | E76: Produksi Harian | F76: 46028.577 | G76: FREE | H76: 46028.922
A77: MK00113 | B77: 528000210 | C77: Muhamad Aldi Agustiana | D77: PROD | E77: Produksi Harian | F77: 46028.578 | G77: FREE | H77: 46028.922
A78: MK00093 | B78: 528000292 | C78: Aditia Nugraha | D78: PROD | E78: Produksi Harian | F78: 46028.579 | G78: FREE | H78: 46028.921
A79: MK00154 | B79: 528000052 | C79: Mustopa | D79: PROD | E79: Produksi Harian | F79: 46028.883 | G79: FREE | H79: 46059.253
... A144: MK00138 | B144: 528000090 | C144: Suganda | D144: PROD | E144: Produksi Harian | F144: 46087.581 | G144: FREE | H144: 46087.921
A145: 128000267 | B145: 528000267 | C145: Bagas Patulloh | D145: LOG | E145: WRM Harian | F145: 46087.653 | G145: FREE | H145: 46148.671
A146: MKOO58 | B146: 528000052 | C146: Mustopa | D146: PROD | E146: Produksi Harian | F146: 46087.823 | G146: FREE | H146: 46198.831
A147: MK00192 | B147: 528000195 | C147: Rahma Sariwati | D147: PROD | E147: Produksi Harian | F147: 46087.895 | G147: FREE | H147: 46148.254
A148: MK00221 | B148: 528000266 | C148: M. Syirajatieq | D148: LOG | E148: WFG Harian | F148: 46087.899 | G148: FREE | H148: 46118.252
A149: MK00109 | B149: 528000262 | C149: Ndari Dwiwanti | D149: PROD | E149: Produksi Harian | F149: 46087.901 | G149: FREE | H149: 46118.251
A150: MK00249 | B150: 528000358 | C150: Lulu Agustin | D150: PROD | E150: Produksi Harian | F150: 46087.903 | G150: FREE | H150: 46118.031
A151: MK00213 | B151: 528000261 | C151: Ergi Ergianto | D151: HRGA | E151: GA Harian | F151: 46087.907 | G151: FREE | H151: 46118.252
A152: MK00150 | B152: 528000283 | C152: Purwanda Sugiri | D152: LOG | E152: WRM Harian | F152: 46087.913 | G152: FREE | H152: 46118.254
A153: MK00082 | B153: 528000291 | C153: Andrian | D153: PROD | E153: Produksi Harian | F153: 46087.913 | G153: FREE | H153: 46118.254
A154: MK00155 | B154: 528000301 | C154: Muhammad Mukti Ridwan | D154: PROD | E154: Produksi Harian | F154: 46087.914 | G154: FREE | H154: 46118.256
A155: MK00249 | B155: 528000358 | C155: Lulu Agustin | D155: PROD | E155: Produksi Harian | F155: 46118.031 | G155: FREE | H155: 46118.586
A156: MK00136 | B156: 528000306 | C156: Windy Olivia | D156: PROD | E156: Produksi Harian | F156: 46118.238 | G156: FREE | H156: 46118.589
...

Sheet REGISTRASI SAAT MASUK PABRIK
A1: NO KARTU MK | B1: NIK | C1: NAMA | D1: TANGGAL | E1: JAM MASUK | F1: SHIFT | G1: NO LOKER
A2: MK0090 | B2: 528000069 | C2: Jajang Ardiansyah | D2: 46164.417 | E2: 0.43628472 | F2: Shift 1
A3: MK00160 | B3: 628000039 | C3: Nani Maryani | D3: 46166.417 | E3: 0.57347222 | F3: Shift 2
A4: MK00112 | B4: 528000016 | C4: Randi Apriyanto | D4: 46170.417 | E4: 0.59222222 | F4: Shift 2
A5: MK00112 | B5: 528000059 | C5: N. Santika Dewi | D5: 46170.417 | E5: 0.6062963 | F5: Shift 2
A6: MK00126 | B6: 528000052 | C6: Mustopa | D6: 46170.417 | E6: 0.60981481 | F6: Shift 2
A7: MK00112 | B7: 528000059 | C7: N. Santika Dewi | D7: 46170.417 | E7: 0.62488426 | F7: Shift 2
A8: CK0093 | B8: 528000055 | C8: Dika Prasetya | D8: 46170.417 | E8: 0.83355324 | F8: Shift 2
A9: MK00156 | B9: 528000201 | C9: Zahwa Amelia Choerunissa | D9: 46170.417 | E9: 0.89846065 | F9: Shift 3
A10: MK00184 | B10: 528000099 | C10: Siti Nurawaliah | D10: 46170.417 | E10: 0.90024306 | F10: Shift 3
A11: MK00116 | B11: 528000244 | C11: Rodian Rifai | D11: 46170.417 | E11: 0.90334491 | F11: Shift 3 | G11: D-26
A12: MK00181 | B12: 528000286 | C12: Imelda Amelia | D12: 46170.417 | E12: 0.90835648 | F12: Shift 3
A13: MK00118 | B13: 528000228 | C13: Banyu Resmi Putri | D13: 46170.417 | E13: 0.91210648 | F13: Shift 3
A14: MK00082 | B14: 528000241 | C14: Balia Nurafif Bilah | D14: 46170.417 | E14: 0.91518519 | F14: Shift 3
A15: MK00155 | B15: 528000212 | C15: Rizal Fauzi | D15: 46170.417 | E15: 0.91671296 | F15: Shift 3
A16: MK00085 | B16: 528000290 | C16: Eval Pranata | D16: 46170.417 | E16: 0.91706019 | F16: Shift 3
A17: MK00136 | B17: 528000274 | C17: Zepri | D17: 46170.417 | E17: 0.91832176 | F17: Shift 3
A18: MK00093 | B18: 528000090 | C18: Suganda | D18: 46170.417 | E18: 0.91858796 | F18: Shift 3
A19: MK00138 | B19: 528000273 | C19: Asep Mulyana | D19: 46170.417 | E19: 0.92143519 | F19: Shift 3
A20: MK00141 | B20: 528000098 | C20: Edi Junaedi | D20: 46171.417 | E20: 0.22613426 | F20: Shift 1 | G20: 2F
A21: MK00151 | B21: 628000061 | C21: Nayla Fadillah Exwantoro | D21: 46171.417 | E21: 0.23168981 | F21: Shift 1
A22: MK00158 | B22: 528000299 | C22: Siti Nurjanah | D22: 46171.417 | E22: 0.24092593 | F22: Shift 1
A23: MK00145 | B23: 528000302 | C23: Henkey gumilar | D23: 46171.417 | E23: 0.24854167 | F23: Shift 1
A24: MK00150 | B24: 628000091 | C24: Devita Handayani | D24: 46171.417 | E24: 0.24989583 | F24: Shift 1
A25: MK00046 | B25: 528000015 | C25: Erwin | D25: 46171.417 | E25: 0.2530787 | F25: Shift 1
A26: MK00155 | B26: 528000282 | C26: Defa Desfiana | D26: 46171.417 | E26: 0.31886574 | F26: Shift 1 | G26: 23C
A27: MK00085 | B27: 528000265 | C27: Muhammad Haerul Rozikin | D27: 46171.417 | E27: 0.32128472 | F27: Shift 1
A28: MK00136 | B28: 528000351 | C28: Mulyana | D28: 46171.417 | E28: 0.33710648 | F28: Shift 1
A29: MK008I | B29: 528000288 | C29: Dede gunawan | D29: 46171.417 | E29: 0.55028935 | F29: Shift 2
A30: MK00116 | B30: 528000306 | C30: Windy Olivia | D30: 46171.417 | E30: 0.57231481 | F30: Shift 2
A31: MK00155 | B31: 628000064 | C31: Silva Alypia | D31: 46171.417 | E31: 0.57951389 | F31: Shift 2
A32: MK00085 | B32: 528000279 | C32: Mahdalena Dalfa Riani | D32: 46171.417 | E32: 0.58271991 | F32: Shift 2
A33: MK00082 | B33: 528000297 | C33: Muhamad Budiana | D33: 46171.417 | E33: 0.58289352 | F33: Shift 2
A34: 628000061 | B34: 528000089 | C34: Santi Susanti | D34: 46171.417 | E34: 0.59180556 | F34: Shift 2
A35: MK00145 | B35: 528000302 | C35: Henkey gumilar | D35: 46171.417 | E35: 0.59856481 | F35: Shift 2
A36: 528000232 | B36: 528000232 | C36: Agung Aji Suhada | D36: 46171.417 | E36: 0.60163194 | F36: Shift 2
A37: MK528000144 | B37: 528000144 | C37: Jodi Hanafi | D37: 46171.417 | E37: 0.60238426 | F37: Shift 2
A38: MK00093 | B38: 528000273 | C38: Asep Mulyana | D38: 46171.417 | E38: 0.66327546 | F38: Shift 2
A39: MK00158 | B39: 528000244 | C39: Rodian Rifai | D39: 46171.417 | E39: 0.8965625 | F39: Shift 3
A40: MKZ0138 | B40: 528000301 | C40: Muhammad Mukti Ridwan | D40: 46171.417 | E40: 0.89696759 | F40: Shift 3
...

Sheet STAFF AKTIF
A1: =IFERROR(__xludf.DUMMYFUNCTION("QUERY(IMPORTRANGE(""https://docs.google.com/spreadsheets/d/1FEoklqOOGVEuHVDC9BVeaIu8tA3fqheZAT3eO9syd2Y/edit?gid=380216187#gid=380216187"", ""STAFF DAM AKTIF!A:AN""), ""SELECT Col1,Col2,Col3,Col26,Col27,Col13,Col15,Col18,Col19,Col38,Col20"")"),"#REF!")

Sheet NON STAFF
A1: =IFERROR(__xludf.DUMMYFUNCTION("QUERY(IMPORTRANGE(""https://docs.google.com/spreadsheets/d/1YuKF0APlK-VpXpbB6ITZTO7ALJdeV-34j7idE7TFcDc/edit?gid=478115743#gid=478115743"", ""AKTIF!B8:X""), ""SELECT Col1,Col2, Col4,Col9, Col11"")"),"No.") | B1: =IFERROR(__xludf.DUMMYFUNCTION("""COMPUTED_VALUE"""),"NIK") | C1: =IFERROR(__xludf.DUMMYFUNCTION("""COMPUTED_VALUE"""),"Nama (sesuai KTP)") | D1: =IFERROR(__xludf.DUMMYFUNCTION("""COMPUTED_VALUE"""),"Bagian") | E1: =IFERROR(__xludf.DUMMYFUNCTION("""COMPUTED_VALUE"""),"DEPT")
A2: =IFERROR(__xludf.DUMMYFUNCTION("""COMPUTED_VALUE"""),1.0) | B2: =IFERROR(__xludf.DUMMYFUNCTION("""COMPUTED_VALUE"""),3.28000001E8) | C2: =IFERROR(__xludf.DUMMYFUNCTION("""COMPUTED_VALUE"""),"RIO GUSTIAWAN") | D2: =IFERROR(__xludf.DUMMYFUNCTION("""COMPUTED_VALUE"""),"ELECTRICAL MAINTENANCE") | E2: =IFERROR(__xludf.DUMMYFUNCTION("""COMPUTED_VALUE"""),"ENGINEERING")
A3: =IFERROR(__xludf.DUMMYFUNCTION("""COMPUTED_VALUE"""),2.0) | B3: =IFERROR(__xludf.DUMMYFUNCTION("""COMPUTED_VALUE"""),3.28000006E8) | C3: =IFERROR(__xludf.DUMMYFUNCTION("""COMPUTED_VALUE"""),"RIZKI") | D3: =IFERROR(__xludf.DUMMYFUNCTION("""COMPUTED_VALUE"""),"TECHNICIAN") | E3: =IFERROR(__xludf.DUMMYFUNCTION("""COMPUTED_VALUE"""),"ENGINEERING")
A4: =IFERROR(__xludf.DUMMYFUNCTION("""COMPUTED_VALUE"""),3.0) | B4: =IFERROR(__xludf.DUMMYFUNCTION("""COMPUTED_VALUE"""),3.28000009E8) | C4: =IFERROR(__xludf.DUMMYFUNCTION("""COMPUTED_VALUE"""),"REZZA FEBRIANA") | D4: =IFERROR(__xludf.DUMMYFUNCTION("""COMPUTED_VALUE"""),"TECHNICIAN") | E4: =IFERROR(__xludf.DUMMYFUNCTION("""COMPUTED_VALUE"""),"ENGINEERING")
A5: =IFERROR(__xludf.DUMMYFUNCTION("""COMPUTED_VALUE"""),4.0) | B5: =IFERROR(__xludf.DUMMYFUNCTION("""COMPUTED_VALUE"""),3.2800001E8) | C5: =IFERROR(__xludf.DUMMYFUNCTION("""COMPUTED_VALUE"""),"DIAZ GHERY JUNIARSYAH RAHMAN") | D5: =IFERROR(__xludf.DUMMYFUNCTION("""COMPUTED_VALUE"""),"TECHNICIAN") | E5: =IFERROR(__xludf.DUMMYFUNCTION("""COMPUTED_VALUE"""),"ENGINEERING")
A6: =IFERROR(__xludf.DUMMYFUNCTION("""COMPUTED_VALUE"""),5.0) | B6: =IFERROR(__xludf.DUMMYFUNCTION("""COMPUTED_VALUE"""),3.28000011E8) | C6: =IFERROR(__xludf.DUMMYFUNCTION("""COMPUTED_VALUE"""),"DENI KUSNADI") | D6: =IFERROR(__xludf.DUMMYFUNCTION("""COMPUTED_VALUE"""),"ADMIN WSP") | E6: =IFERROR(__xludf.DUMMYFUNCTION("""COMPUTED_VALUE"""),"LOGISTIC")
A7: =IFERROR(__xludf.DUMMYFUNCTION("""COMPUTED_VALUE"""),6.0) | B7: =IFERROR(__xludf.DUMMYFUNCTION("""COMPUTED_VALUE"""),3.28000022E8) | C7: =IFERROR(__xludf.DUMMYFUNCTION("""COMPUTED_VALUE"""),"AZHAR AIZAD ALFARIDZI ") | D7: =IFERROR(__xludf.DUMMYFUNCTION("""COMPUTED_VALUE"""),"OPERATOR PRODUCTION") | E7: =IFERROR(__xludf.DUMMYFUNCTION("""COMPUTED_VALUE"""),"PRODUCTION")
A8: =IFERROR(__xludf.DUMMYFUNCTION("""COMPUTED_VALUE"""),7.0) | B8: =IFERROR(__xludf.DUMMYFUNCTION("""COMPUTED_VALUE"""),3.28000023E8) | C8: =IFERROR(__xludf.DUMMYFUNCTION("""COMPUTED_VALUE"""),"KEPIN NUGRAHA") | D8: =IFERROR(__xludf.DUMMYFUNCTION("""COMPUTED_VALUE"""),"OPERATOR PRODUCTION") | E8: =IFERROR(__xludf.DUMMYFUNCTION("""COMPUTED_VALUE"""),"PRODUCTION")
A9: =IFERROR(__xludf.DUMMYFUNCTION("""COMPUTED_VALUE"""),8.0) | B9: =IFERROR(__xludf.DUMMYFUNCTION("""COMPUTED_VALUE"""),3.28000026E8) | C9: =IFERROR(__xludf.DUMMYFUNCTION("""COMPUTED_VALUE"""),"DEDE WAHYUDIN ") | D9: =IFERROR(__xludf.DUMMYFUNCTION("""COMPUTED_VALUE"""),"OPERATOR PRODUCTION") | E9: =IFERROR(__xludf.DUMMYFUNCTION("""COMPUTED_VALUE"""),"PRODUCTION")
A10: =IFERROR(__xludf.DUMMYFUNCTION("""COMPUTED_VALUE"""),9.0) | B10: =IFERROR(__xludf.DUMMYFUNCTION("""COMPUTED_VALUE"""),3.28000027E8) | C10: =IFERROR(__xludf.DUMMYFUNCTION("""COMPUTED_VALUE"""),"GIGIN GINANJAR") | D10: =IFERROR(__xludf.DUMMYFUNCTION("""COMPUTED_VALUE"""),"OPERATOR PRODUCTION") | E10: =IFERROR(__xludf.DUMMYFUNCTION("""COMPUTED_VALUE"""),"PRODUCTION")
A11: =IFERROR(__xludf.DUMMYFUNCTION("""COMPUTED_VALUE"""),10.0) | B11: =IFERROR(__xludf.DUMMYFUNCTION("""COMPUTED_VALUE"""),3.28000028E8) | C11: =IFERROR(__xludf.DUMMYFUNCTION("""COMPUTED_VALUE"""),"TISNA GINANJAR") | D11: =IFERROR(__xludf.DUMMYFUNCTION("""COMPUTED_VALUE"""),"OPERATOR PRODUCTION") | E11: =IFERROR(__xludf.DUMMYFUNCTION("""COMPUTED_VALUE"""),"PRODUCTION")
A12: =IFERROR(__xludf.DUMMYFUNCTION("""COMPUTED_VALUE"""),11.0) | B12: =IFERROR(__xludf.DUMMYFUNCTION("""COMPUTED_VALUE"""),3.2800003E8) | C12: =IFERROR(__xludf.DUMMYFUNCTION("""COMPUTED_VALUE"""),"DAVA PUTRA YUDIANSYAH") | D12: =IFERROR(__xludf.DUMMYFUNCTION("""COMPUTED_VALUE"""),"OPERATOR PRODUCTION") | E12: =IFERROR(__xludf.DUMMYFUNCTION("""COMPUTED_VALUE"""),"PRODUCTION")
A13: =IFERROR(__xludf.DUMMYFUNCTION("""COMPUTED_VALUE"""),12.0) | B13: =IFERROR(__xludf.DUMMYFUNCTION("""COMPUTED_VALUE"""),3.28000032E8) | C13: =IFERROR(__xludf.DUMMYFUNCTION("""COMPUTED_VALUE"""),"RUBY SUBASTIAN") | D13: =IFERROR(__xludf.DUMMYFUNCTION("""COMPUTED_VALUE"""),"OPERATOR PRODUCTION") | E13: =IFERROR(__xludf.DUMMYFUNCTION("""COMPUTED_VALUE"""),"PRODUCTION")
A14: =IFERROR(__xludf.DUMMYFUNCTION("""COMPUTED_VALUE"""),13.0) | B14: =IFERROR(__xludf.DUMMYFUNCTION("""COMPUTED_VALUE"""),3.28000033E8) | C14: =IFERROR(__xludf.DUMMYFUNCTION("""COMPUTED_VALUE"""),"HENDRA") | D14: =IFERROR(__xludf.DUMMYFUNCTION("""COMPUTED_VALUE"""),"OPERATOR PRODUCTION") | E14: =IFERROR(__xludf.DUMMYFUNCTION("""COMPUTED_VALUE"""),"PRODUCTION")
A15: =IFERROR(__xludf.DUMMYFUNCTION("""COMPUTED_VALUE"""),14.0) | B15: =IFERROR(__xludf.DUMMYFUNCTION("""COMPUTED_VALUE"""),3.28000038E8) | C15: =IFERROR(__xludf.DUMMYFUNCTION("""COMPUTED_VALUE"""),"MESTHY PEBRIYANTI") | D15: =IFERROR(__xludf.DUMMYFUNCTION("""COMPUTED_VALUE"""),"QC LAB") | E15: =IFERROR(__xludf.DUMMYFUNCTION("""COMPUTED_VALUE"""),"QUALITY AND RESEARCH & DEVELOPMENT")
A16: =IFERROR(__xludf.DUMMYFUNCTION("""COMPUTED_VALUE"""),15.0) | B16: =IFERROR(__xludf.DUMMYFUNCTION("""COMPUTED_VALUE"""),3.28000039E8) | C16: =IFERROR(__xludf.DUMMYFUNCTION("""COMPUTED_VALUE"""),"DESTY MARLIANI") | D16: =IFERROR(__xludf.DUMMYFUNCTION("""COMPUTED_VALUE"""),"QC LAB") | E16: =IFERROR(__xludf.DUMMYFUNCTION("""COMPUTED_VALUE"""),"QUALITY AND RESEARCH & DEVELOPMENT")
A17: =IFERROR(__xludf.DUMMYFUNCTION("""COMPUTED_VALUE"""),16.0) | B17: =IFERROR(__xludf.DUMMYFUNCTION("""COMPUTED_VALUE"""),3.28000041E8) | C17: =IFERROR(__xludf.DUMMYFUNCTION("""COMPUTED_VALUE"""),"BUNGA ADELIYA") | D17: =IFERROR(__xludf.DUMMYFUNCTION("""COMPUTED_VALUE"""),"PACKER") | E17: =IFERROR(__xludf.DUMMYFUNCTION("""COMPUTED_VALUE"""),"PRODUCTION")
A18: =IFERROR(__xludf.DUMMYFUNCTION("""COMPUTED_VALUE"""),17.0) | B18: =IFERROR(__xludf.DUMMYFUNCTION("""COMPUTED_VALUE"""),3.28000043E8) | C18: =IFERROR(__xludf.DUMMYFUNCTION("""COMPUTED_VALUE"""),"ANDINI NOVIA RAMADANI") | D18: =IFERROR(__xludf.DUMMYFUNCTION("""COMPUTED_VALUE"""),"PACKER") | E18: =IFERROR(__xludf.DUMMYFUNCTION("""COMPUTED_VALUE"""),"PRODUCTION")
A19: =IFERROR(__xludf.DUMMYFUNCTION("""COMPUTED_VALUE"""),18.0) | B19: =IFERROR(__xludf.DUMMYFUNCTION("""COMPUTED_VALUE"""),3.28000052E8) | C19: =IFERROR(__xludf.DUMMYFUNCTION("""COMPUTED_VALUE"""),"DIMAS NUGROHO") | D19: =IFERROR(__xludf.DUMMYFUNCTION("""COMPUTED_VALUE"""),"ADMIN WSP") | E19: =IFERROR(__xludf.DUMMYFUNCTION("""COMPUTED_VALUE"""),"LOGISTIC")
A20: =IFERROR(__xludf.DUMMYFUNCTION("""COMPUTED_VALUE"""),19.0) | B20: =IFERROR(__xludf.DUMMYFUNCTION("""COMPUTED_VALUE"""),3.28000053E8) | C20: =IFERROR(__xludf.DUMMYFUNCTION("""COMPUTED_VALUE"""),"VERA PURBA") | D20: =IFERROR(__xludf.DUMMYFUNCTION("""COMPUTED_VALUE"""),"PRODUCTION ADMIN") | E20: =IFERROR(__xludf.DUMMYFUNCTION("""COMPUTED_VALUE"""),"PRODUCTION")
A21: =IFERROR(__xludf.DUMMYFUNCTION("""COMPUTED_VALUE"""),20.0) | B21: =IFERROR(__xludf.DUMMYFUNCTION("""COMPUTED_VALUE"""),3.28000063E8) | C21: =IFERROR(__xludf.DUMMYFUNCTION("""COMPUTED_VALUE"""),"RIZKI AGUNG") | D21: =IFERROR(__xludf.DUMMYFUNCTION("""COMPUTED_VALUE"""),"OPERATOR PRODUCTION") | E21: =IFERROR(__xludf.DUMMYFUNCTION("""COMPUTED_VALUE"""),"PRODUCTION")
A22: =IFERROR(__xludf.DUMMYFUNCTION("""COMPUTED_VALUE"""),21.0) | B22: =IFERROR(__xludf.DUMMYFUNCTION("""COMPUTED_VALUE"""),3.28000066E8) | C22: =IFERROR(__xludf.DUMMYFUNCTION("""COMPUTED_VALUE"""),"NADILA NAZIWA SOPIAN") | D22: =IFERROR(__xludf.DUMMYFUNCTION("""COMPUTED_VALUE"""),"QC LAB") | E22: =IFERROR(__xludf.DUMMYFUNCTION("""COMPUTED_VALUE"""),"QUALITY AND RESEARCH & DEVELOPMENT")
A23: =IFERROR(__xludf.DUMMYFUNCTION("""COMPUTED_VALUE"""),22.0) | B23: =IFERROR(__xludf.DUMMYFUNCTION("""COMPUTED_VALUE"""),3.28000068E8) | C23: =IFERROR(__xludf.DUMMYFUNCTION("""COMPUTED_VALUE"""),"NADINE RIEZKI GHEFIRA") | D23: =IFERROR(__xludf.DUMMYFUNCTION("""COMPUTED_VALUE"""),"QC LAB") | E23: =IFERROR(__xludf.DUMMYFUNCTION("""COMPUTED_VALUE"""),"QUALITY AND RESEARCH & DEVELOPMENT")
A24: =IFERROR(__xludf.DUMMYFUNCTION("""COMPUTED_VALUE"""),23.0) | B24: =IFERROR(__xludf.DUMMYFUNCTION("""COMPUTED_VALUE"""),3.2800007E8) | C24: =IFERROR(__xludf.DUMMYFUNCTION("""COMPUTED_VALUE"""),"BAYU AJIE PANGESTU") | D24: =IFERROR(__xludf.DUMMYFUNCTION("""COMPUTED_VALUE"""),"QC PATROL") | E24: =IFERROR(__xludf.DUMMYFUNCTION("""COMPUTED_VALUE"""),"QUALITY AND RESEARCH & DEVELOPMENT")
A25: =IFERROR(__xludf.DUMMYFUNCTION("""COMPUTED_VALUE"""),24.0) | B25: =IFERROR(__xludf.DUMMYFUNCTION("""COMPUTED_VALUE"""),3.28000072E8) | C25: =IFERROR(__xludf.DUMMYFUNCTION("""COMPUTED_VALUE"""),"ANISA FITALOKA") | D25: =IFERROR(__xludf.DUMMYFUNCTION("""COMPUTED_VALUE"""),"RF") | E25: =IFERROR(__xludf.DUMMYFUNCTION("""COMPUTED_VALUE"""),"PRODUCTION")
A26: =IFERROR(__xludf.DUMMYFUNCTION("""COMPUTED_VALUE"""),25.0) | B26: =IFERROR(__xludf.DUMMYFUNCTION("""COMPUTED_VALUE"""),3.2800008E8) | C26: =IFERROR(__xludf.DUMMYFUNCTION("""COMPUTED_VALUE"""),"ILHAM PAOJI MUHAROM") | D26: =IFERROR(__xludf.DUMMYFUNCTION("""COMPUTED_VALUE"""),"OPERATOR FORKLIFT") | E26: =IFERROR(__xludf.DUMMYFUNCTION("""COMPUTED_VALUE"""),"LOGISTIC")
A27: =IFERROR(__xludf.DUMMYFUNCTION("""COMPUTED_VALUE"""),26.0) | B27: =IFERROR(__xludf.DUMMYFUNCTION("""COMPUTED_VALUE"""),3.28000088E8) | C27: =IFERROR(__xludf.DUMMYFUNCTION("""COMPUTED_VALUE"""),"MEISY TRESA HANDAYANI") | D27: =IFERROR(__xludf.DUMMYFUNCTION("""COMPUTED_VALUE"""),"RF") | E27: =IFERROR(__xludf.DUMMYFUNCTION("""COMPUTED_VALUE"""),"PRODUCTION")
A28: =IFERROR(__xludf.DUMMYFUNCTION("""COMPUTED_VALUE"""),27.0) | B28: =IFERROR(__xludf.DUMMYFUNCTION("""COMPUTED_VALUE"""),3.28000095E8) | C28: =IFERROR(__xludf.DUMMYFUNCTION("""COMPUTED_VALUE"""),"AGUS JONI") | D28: =IFERROR(__xludf.DUMMYFUNCTION("""COMPUTED_VALUE"""),"OPERATOR PRODUCTION") | E28: =IFERROR(__xludf.DUMMYFUNCTION("""COMPUTED_VALUE"""),"PRODUCTION")
A29: =IFERROR(__xludf.DUMMYFUNCTION("""COMPUTED_VALUE"""),28.0) | B29: =IFERROR(__xludf.DUMMYFUNCTION("""COMPUTED_VALUE"""),3.28000097E8) | C29: =IFERROR(__xludf.DUMMYFUNCTION("""COMPUTED_VALUE"""),"YOGI RUDIYANTO") | D29: =IFERROR(__xludf.DUMMYFUNCTION("""COMPUTED_VALUE"""),"PIC AREA") | E29: =IFERROR(__xludf.DUMMYFUNCTION("""COMPUTED_VALUE"""),"LOGISTIC")
A30: =IFERROR(__xludf.DUMMYFUNCTION("""COMPUTED_VALUE"""),29.0) | B30: =IFERROR(__xludf.DUMMYFUNCTION("""COMPUTED_VALUE"""),3.28000104E8) | C30: =IFERROR(__xludf.DUMMYFUNCTION("""COMPUTED_VALUE"""),"TASYA APRIANI") | D30: =IFERROR(__xludf.DUMMYFUNCTION("""COMPUTED_VALUE"""),"PACKER") | E30: =IFERROR(__xludf.DUMMYFUNCTION("""COMPUTED_VALUE"""),"PRODUCTION")
A31: =IFERROR(__xludf.DUMMYFUNCTION("""COMPUTED_VALUE"""),30.0) | B31: =IFERROR(__xludf.DUMMYFUNCTION("""COMPUTED_VALUE"""),3.28000108E8) | C31: =IFERROR(__xludf.DUMMYFUNCTION("""COMPUTED_VALUE"""),"AHMAD NUR FAJAR") | D31: =IFERROR(__xludf.DUMMYFUNCTION("""COMPUTED_VALUE"""),"OPERATOR PRODUCTION") | E31: =IFERROR(__xludf.DUMMYFUNCTION("""COMPUTED_VALUE"""),"PRODUCTION")
A32: =IFERROR(__xludf.DUMMYFUNCTION("""COMPUTED_VALUE"""),31.0) | B32: =IFERROR(__xludf.DUMMYFUNCTION("""COMPUTED_VALUE"""),3.28000109E8) | C32: =IFERROR(__xludf.DUMMYFUNCTION("""COMPUTED_VALUE"""),"RIZKY PRADANA R") | D32: =IFERROR(__xludf.DUMMYFUNCTION("""COMPUTED_VALUE"""),"OPERATOR PRODUCTION") | E32: =IFERROR(__xludf.DUMMYFUNCTION("""COMPUTED_VALUE"""),"PRODUCTION")
A33: =IFERROR(__xludf.DUMMYFUNCTION("""COMPUTED_VALUE"""),32.0) | B33: =IFERROR(__xludf.DUMMYFUNCTION("""COMPUTED_VALUE"""),3.2800011E8) | C33: =IFERROR(__xludf.DUMMYFUNCTION("""COMPUTED_VALUE"""),"PRATAMA WAHYU SAPUTRO") | D33: =IFERROR(__xludf.DUMMYFUNCTION("""COMPUTED_VALUE"""),"OPERATOR PRODUCTION") | E33: =IFERROR(__xludf.DUMMYFUNCTION("""COMPUTED_VALUE"""),"PRODUCTION")
A34: =IFERROR(__xludf.DUMMYFUNCTION("""COMPUTED_VALUE"""),33.0) | B34: =IFERROR(__xludf.DUMMYFUNCTION("""COMPUTED_VALUE"""),3.28000111E8) | C34: =IFERROR(__xludf.DUMMYFUNCTION("""COMPUTED_VALUE"""),"KESLERIA") | D34: =IFERROR(__xludf.DUMMYFUNCTION("""COMPUTED_VALUE"""),"PACKER") | E34: =IFERROR(__xludf.DUMMYFUNCTION("""COMPUTED_VALUE"""),"PRODUCTION")
A35: =IFERROR(__xludf.DUMMYFUNCTION("""COMPUTED_VALUE"""),34.0) | B35: =IFERROR(__xludf.DUMMYFUNCTION("""COMPUTED_VALUE"""),3.28000112E8) | C35: =IFERROR(__xludf.DUMMYFUNCTION("""COMPUTED_VALUE"""),"FIRDAWATI") | D35: =IFERROR(__xludf.DUMMYFUNCTION("""COMPUTED_VALUE"""),"PACKER") | E35: =IFERROR(__xludf.DUMMYFUNCTION("""COMPUTED_VALUE"""),"PRODUCTION")
A36: =IFERROR(__xludf.DUMMYFUNCTION("""COMPUTED_VALUE"""),35.0) | B36: =IFERROR(__xludf.DUMMYFUNCTION("""COMPUTED_VALUE"""),3.28000115E8) | C36: =IFERROR(__xludf.DUMMYFUNCTION("""COMPUTED_VALUE"""),"SELY RISDIYANI") | D36: =IFERROR(__xludf.DUMMYFUNCTION("""COMPUTED_VALUE"""),"PACKER") | E36: =IFERROR(__xludf.DUMMYFUNCTION("""COMPUTED_VALUE"""),"PRODUCTION")
A37: =IFERROR(__xludf.DUMMYFUNCTION("""COMPUTED_VALUE"""),36.0) | B37: =IFERROR(__xludf.DUMMYFUNCTION("""COMPUTED_VALUE"""),3.28000122E8) | C37: =IFERROR(__xludf.DUMMYFUNCTION("""COMPUTED_VALUE"""),"SENDI") | D37: =IFERROR(__xludf.DUMMYFUNCTION("""COMPUTED_VALUE"""),"OPERATOR PRODUCTION") | E37: =IFERROR(__xludf.DUMMYFUNCTION("""COMPUTED_VALUE"""),"PRODUCTION")
A38: =IFERROR(__xludf.DUMMYFUNCTION("""COMPUTED_VALUE"""),37.0) | B38: =IFERROR(__xludf.DUMMYFUNCTION("""COMPUTED_VALUE"""),3.28000129E8) | C38: =IFERROR(__xludf.DUMMYFUNCTION("""COMPUTED_VALUE"""),"AHMAD SYAEFUDIN LATIEF") | D38: =IFERROR(__xludf.DUMMYFUNCTION("""COMPUTED_VALUE"""),"OPERATOR PRODUCTION") | E38: =IFERROR(__xludf.DUMMYFUNCTION("""COMPUTED_VALUE"""),"PRODUCTION")
A39: =IFERROR(__xludf.DUMMYFUNCTION("""COMPUTED_VALUE"""),38.0) | B39: =IFERROR(__xludf.DUMMYFUNCTION("""COMPUTED_VALUE"""),3.2800013E8) | C39: =IFERROR(__xludf.DUMMYFUNCTION("""COMPUTED_VALUE"""),"AGIL AGUSTIAWAN") | D39: =IFERROR(__xludf.DUMMYFUNCTION("""COMPUTED_VALUE"""),"OPERATOR PRODUCTION") | E39: =IFERROR(__xludf.DUMMYFUNCTION("""COMPUTED_VALUE"""),"PRODUCTION")
A40: =IFERROR(__xludf.DUMMYFUNCTION("""COMPUTED_VALUE"""),39.0) | B40: =IFERROR(__xludf.DUMMYFUNCTION("""COMPUTED_VALUE"""),3.28000132E8) | C40: =IFERROR(__xludf.DUMMYFUNCTION("""COMPUTED_VALUE"""),"FIRYAL FITRIYAH ABID SADIAH") | D40: =IFERROR(__xludf.DUMMYFUNCTION("""COMPUTED_VALUE"""),"QC PATROL") | E40: =IFERROR(__xludf.DUMMYFUNCTION("""COMPUTED_VALUE"""),"QUALITY AND RESEARCH & DEVELOPMENT")
...

Sheet MITRA KERJA
A1: NIK | B1: Nama Karyawan | C1: Jenis Kekaryawanan | D1: Department | E1: Posisi | F1: Tanggal Scan IRIS | G1: ID IRIS | H1: Data Enrollment | I1: Status Perubahan Perbedaan Data
A2: 428000004 | B2: ADI MUZAKI | C2: Mitra Kerja | D2: HRGA | E2: GA Vendor | F2: 2025-5-13 | G2: 0000122823 | I2: Completed
A3: 428000006 | B3: BAGAS JUAN PRATAMA | C3: Mitra Kerja | D3: HRGA | E3: GA Vendor | F3: 2025-5-5 | G3: 0000122123 | I3: -
A4: 428000011 | B4: DINO DRAJAT | C4: Mitra Kerja | D4: HRGA | E4: GA Vendor | F4: 2025-5-9 | G4: 0000122639 | I4: -
A5: 428000012 | B5: RIDKI MAULANA | C5: Mitra Kerja | D5: HRGA | E5: GA Vendor | F5: 2025-5-10 | G5: 0000122722 | I5: -
A6: 428000014 | B6: ADITYA SAPUTRA | C6: Mitra Kerja | D6: HRGA | E6: GA Vendor | F6: 2025-5-5 | G6: 0000122106 | I6: -
A7: 428000015 | B7: MOCHAMMAD AJAR NURJI | C7: Mitra Kerja | D7: HRGA | E7: GA Vendor | F7: 2025-5-5 | G7: 0000122108 | I7: -
A8: 428000020 | B8: MUSLIM | C8: Mitra Kerja | D8: HRGA | E8: GA Vendor | F8: 2025-5-5 | G8: 0000122121 | I8: -
A9: 428000021 | B9: CARI IRAWAN | C9: Mitra Kerja | D9: HRGA | E9: GA Vendor | F9: 2022-9-6 | G9: 0000055031 | I9: -
A10: 428000024 | B10: ADI MAULANA | C10: Mitra Kerja | D10: HRGA | E10: GA Vendor | F10: 2025-5-8 | G10: 0000122597 | I10: -
A11: 428000030 | B11: ERDI HERDIANSYAH | C11: Mitra Kerja | D11: HRGA | E11: GA Vendor | F11: 2025-5-8 | G11: 0000122592 | I11: -
A12: 428000031 | B12: SARIP HIDAYAT | C12: Mitra Kerja | D12: HRGA | E12: GA Vendor | F12: 2025-5-6 | G12: 0000122300 | I12: -
A13: 428000032 | B13: HERI HOERUDIN | C13: Mitra Kerja | D13: HRGA | E13: GA Vendor | F13: 2025-5-13 | G13: 0000122814 | I13: Completed
... A35: 428000069 | B35: GITHA FAHSYA APRILIYUNIARNI JUANDI | C35: Mitra Kerja | D35: HRGA | E35: GA Vendor | F35: 2025-5-5 | G35: 0000122098 | I35: -
A36: 428000070 | B36: ATEP HIDAYAT | C36: Mitra Kerja | D36: HRGA | E36: GA Vendor
A37: 428000071 | B37: DADI KURNIADI | C37: Mitra Kerja | D37: HRGA | E37: GA Vendor | F37: 2025-5-6 | G37: 0000122287 | I37: -
A38: 428000073 | B38: FIKRI YANDIKA RAMADHAN | C38: Mitra Kerja | D38: HRGA | E38: GA Vendor | F38: 2025-5-28 | G38: 0000123565 | I38: -
A39: 428000074 | B39: SUNARYO | C39: Mitra Kerja | D39: HRGA | E39: GA Vendor | F39: 2025-7-5 | G39: 0000125311 | I39: -
A40: 428000075 | B40: DINA VEBRIANTI | C40: Mitra Kerja | D40: HRGA | E40: GA Vendor | F40: 2025-7-5 | G40: 0000125307 | I40: -
A41: 428000076 | B41: ELFAN TAUFIK S | C41: Mitra Kerja | D41: HRGA | E41: GA Vendor | F41: 2025-7-5 | G41: 0000125322 | I41: To Be Corrected
A42: 428000077 | B42: EKA PRADITA | C42: Mitra Kerja | D42: HRGA | E42: GA Vendor | F42: 2025-7-5 | G42: 0000125315 | I42: -
A43: 428000078 | B43: ARIF MAULANA Y | C43: Mitra Kerja | D43: HRGA | E43: GA Vendor | F43: 2025-7-5 | G43: 0000125314 | I43: To Be Corrected
A44: 428000079 | B44: TAOPIK HIDAYAT | C44: Mitra Kerja | D44: HRGA | E44: GA Vendor | F44: 2025-7-5 | G44: 0000125318 | I44: -
A45: 428000080 | B45: ROHIM | C45: Mitra Kerja | D45: HRGA | E45: GA Vendor | F45: 2025-7-5 | G45: 0000125309 | I45: -
A46: 428000081 | B46: M TANTAN T | C46: Mitra Kerja | D46: HRGA | E46: GA Vendor | F46: 2025-7-5 | G46: 0000125308 | I46: To Be Corrected
A47: 428000083 | B47: RIKI SONJAYA | C47: Mitra Kerja | D47: HRGA | E47: GA Vendor | F47: 2025-7-5 | G47: 0000125313 | I47: -
A48: 428000084 | B48: EKA SETIAWAN | C48: Mitra Kerja | D48: HRGA | E48: GA Vendor | F48: 2025-7-5 | G48: 0000125312 | I48: -
... A84: 528000132 | B84: Giopani | C84: Mitra Kerja | D84: LOG | E84: WRM Harian | F84: 2025-5-10 | G84: 0000122717 | I84: Completed
A85: 528000144 | B85: Jodi Hanafi | C85: Mitra Kerja | D85: LOG | E85: WRM Harian
A86: 528000146 | B86: Deny Afrizal | C86: Mitra Kerja | D86: PROD | E86: Produksi Harian | F86: 2025-5-14 | G86: 0000122873 | I86: To Be Corrected
A87: 528000149 | B87: Tio Fernanda | C87: Mitra Kerja | D87: LOG | E87: WRM Harian | F87: 2025-5-10 | G87: 0000122720 | I87: Completed
A88: 528000155 | B88: Dea Amelia | C88: Mitra Kerja | D88: PROD | E88: Produksi Harian
A89: 528000158 | B89: Eva Nurjanah | C89: Mitra Kerja | D89: PROD | E89: Produksi Harian | F89: 2025-5-16 | G89: 0000123074 | I89: Completed
A90: 528000194 | B90: Tanti Haryanti | C90: Mitra Kerja | D90: PROD | E90: Produksi Borongan
A91: 528000195 | B91: Rahma Sariwati | C91: Mitra Kerja | D91: PROD | E91: Produksi Harian | F91: 2025-5-9 | G91: 0000122648 | I91: -
A92: 528000196 | B92: Ropika Handayani | C92: Mitra Kerja | D92: PROD | E92: Produksi Harian | F92: 2025-5-9 | G92: 0000122672 | I92: Completed
A93: 528000198 | B93: Herlan Darus Maulana | C93: Mitra Kerja | D93: ENG | E93: Engineering Harian
A94: 528000199 | B94: Giparel Hamdani | C94: Mitra Kerja | D94: LOG | E94: WRM Harian | F94: 2025-5-9 | G94: 0000122692 | I94: -
A95: 528000201 | B95: Zahwa Amelia Choerunissa | C95: Mitra Kerja | D95: PROD | E95: Produksi Harian | F95: 2025-5-19 | G95: 0000123127 | I95: -
A96: 528000202 | B96: Asep Saepudin | C96: Mitra Kerja | D96: LOG | E96: WRM Harian
...

Sheet STAFF NON AKTIF
A1: =IFERROR(__xludf.DUMMYFUNCTION("QUERY(IMPORTRANGE(""https://docs.google.com/spreadsheets/d/1FEoklqOOGVEuHVDC9BVeaIu8tA3fqheZAT3eO9syd2Y/edit?gid=380216187#gid=380216187"", ""NON AKTIF!A:AN""), ""SELECT Col1,Col2,Col3,Col23,Col24"")"),"#REF!")

Sheet REGISTRASI SAAT KELUAR PABRIK
A1: NO KARTU MK | B1: NIK | C1: NAMA | D1: TANGGAL | E1: JAM KELUAR | F1: SHIFT | G1: NO LOKER
A2: MK0090 | B2: 528000069 | C2: Jajang Ardiansyah | D2: 46164.417 | E2: 0.43875 | F2: Shift 1
A3: MK00112 | B3: 528000016 | C3: Randi Apriyanto | D3: 46170.417 | E3: 0.59494213 | F3: Shift 1
A4: MK00112 | B4: 528000059 | C4: N. Santika Dewi | D4: 46170.417 | E4: 0.60777778 | F4: Shift 1
A5: MK00126 | B5: 528000052 | C5: Mustopa | D5: 46170.417 | E5: 0.6103588 | F5: Shift 1
A6: MK00093 | B6: 528000090 | C6: Suganda | D6: 46171.417 | E6: 0.25300926 | F6: Shift 3
A7: MK00082 | B7: 528000241 | C7: Balia Nurafif Bilah | D7: 46171.417 | E7: 0.25396991 | F7: Shift 3
A8: MK00136 | B8: 528000274 | C8: Zepri | D8: 46171.417 | E8: 0.2552662 | F8: Shift 3
A9: MK00085 | B9: 528000290 | C9: Eval Pranata | D9: 46171.417 | E9: 0.25560185 | F9: Shift 3
A10: MK00116 | B10: 528000244 | C10: Rodian Rifai | D10: 46171.417 | E10: 0.25616898 | F10: Shift 3
A11: MK00138 | B11: 528000273 | C11: Asep Mulyana | D11: 46171.417 | E11: 0.25662037 | F11: Shift 3
A12: MK00155 | B12: 528000212 | C12: Rizal Fauzi | D12: 46171.417 | E12: 0.27362269 | F12: Shift 3
A13: MK00136 | B13: 528000351 | C13: Mulyana | D13: 46171.417 | E13: 0.54587963 | F13: Shift 1
... A73: MK00109 | B73: 528000262 | C73: Ndari Dwiwanti | D73: 46143.417 | E73: 0.25289352 | F73: Shift 3
A74: MK00154 | B74: 528000052 | C74: Mustopa | D74: 46143.417 | E74: 0.25292824 | F74: Shift 3 | G74: A 10
A75: MK00250 | B75: 528000306 | C75: Windy Olivia | D75: 46143.417 | E75: 0.25299769 | F75: Shift 3
A76: MK00150 | B76: 528000283 | C76: Purwanda Sugiri | D76: 46143.417 | E76: 0.25320602 | F76: Shift 3
A77: MK00126 | B77: 528000266 | C77: M. Syirajatieq | D77: 46143.417 | E77: 0.25326389 | F77: Shift 3
A78: MK00082 | B78: 528000291 | C78: Andrian | D78: 46143.417 | E78: 0.25394676 | F78: Shift 3
A79: MK00156 | B79: 528000195 | C79: Rahma Sariwati | D79: 46143.417 | E79: 0.25416667 | F79: Shift 3
A80: MK00145 | B80: 528000015 | C80: Erwin | D80: 46143.417 | E80: 0.25434028 | F80: Shift 3
A81: MK00056 | B81: 528000301 | C81: Muhammad Mukti Ridwan | D81: 46143.417 | E81: 0.25741898 | F81: Shift 3
A82: MK00118 | B82: 528000228 | C82: Banyu Resmi Putri | D82: 46143.417 | E82: 0.33512731 | F82: Shift 1
A83: MK00155 | B83: 528000298 | C83: Desta Cahaya Pratama | D83: 46143.417 | E83: 0.58533565 | F83: Shift 1
A84: MK00181 | B84: 528000299 | C84: Siti Nurjanah | D84: 46143.417 | E84: 0.58649306 | F84: Shift 1
A85: MK00184 | B85: 528000305 | C85: Puji Puspita | D85: 46143.417 | E85: 0.5866088 | F85: Shift 1
A86: MK00116 | B86: 528000098 | C86: Edi Junaedi | D86: 46143.417 | E86: 0.58679398 | F86: Shift 1
... A100: MK00199 | B100: 528000261 | C100: Ergi Ergianto | D100: 46144.417 | E100: 0.25202546 | F100: Shift 3
A101: MK00085 | B101: 528000052 | C101: Mustopa | D101: 46144.417 | E101: 0.25244213 | F101: Shift 3 | G101: A 10
A102: MK00192 | B102: 528000283 | C102: Purwanda Sugiri | D102: 46144.417 | E102: 0.25263889 | F102: Shift 3
A103: MK00093 | B103: 528000291 | C103: Andrian | D103: 46144.417 | E103: 0.25296296 | F103: Shift 3
A104: MK00205 | B104: 528000301 | C104: Muhammad Mukti Ridwan | D104: 46144.417 | E104: 0.25384259 | F104: Shift 3
A105: MK00154 | B105: 528000203 | C105: Yudha Ramdhan Putra | D105: 46144.417 | E105: 0.33010417 | F105: Shift 3
A106: MK00118 | B106: 528000015 | C106: Erwin | D106: 46144.417 | E106: 0.33042824 | F106: Shift 3
A107: MK528000144 | B107: 528000144 | C107: Jodi Hanafi | D107: 46144.417 | E107: 0.33180556 | F107: Shift 3
A108: MK00150 | B108: 528000144 | C108: Jodi Hanafi | D108: 46144.417 | E108: 0.33418981 | F108: Shift 1
A109: MK0155 | B109: 528000212 | C109: Rizal Fauzi | D109: 46144.417 | E109: 0.56311343 | F109: Shift 1
A110: MK00148 | B110: 528000201 | C110: Zahwa Amelia Choerunissa | D110: 46144.417 | E110: 0.56861111 | F110: Shift 1
A111: MK00113 | B111: 528000099 | C111: Siti Nurawaliah | D111: 46144.417 | E111: 0.57015046 | F111: Shift 1
A112: MK00207 | B112: 528000286 | C112: Imelda Amelia | D112: 46144.417 | E112: 0.57025463 | F112: Shift 1
...

Sheet ABSEN IN OUT MK
A1: TANGGAL | B1: NIK | C1: NAMA | D1: DEPARTEMEN | E1: JABATAN | F1: JAM MASUK | G1: JAM KELUAR | H1: STATUS | I1: NO KARTU MK | J1: NO LOKER
A2: 07/03/2026 | B2: 528000052 | C2: Mustopa | D2: PROD | E2: Produksi Harian | F2: 21:05:27 | H2: DI DALAM | I2: MK00154
A3: 07/03/2026 | B3: 528000262 | C3: Ndari Dwiwanti | D3: PROD | E3: Produksi Harian | F3: 21:47:19 | H3: DI DALAM | I3: MK00088
A4: 07/03/2026 | B4: 528000283 | C4: Purwanda Sugiri | D4: LOG | E4: WRM Harian | F4: 21:53:45 | H4: DI DALAM | I4: MK00218
A5: 07/03/2026 | B5: 528000291 | C5: Andrian | D5: PROD | E5: Produksi Harian | F5: 21:53:13 | H5: DI DALAM | I5: MK00249
A6: 07/03/2026 | B6: 528000323 | C6: Dian Hamidah | D6: PROD | E6: Produksi Harian | F6: 21:42:05 | H6: DI DALAM | I6: MK00181
A7: 07/03/2026 | B7: 528000336 | C7: Ali Nurhanafi | D7: PROD | E7: Produksi Harian | F7: 21:03:29 | H7: DI DALAM | I7: MK00185
A8: 07/03/2026 | B8: 528000358 | C8: Lulu Agustin | D8: PROD | E8: Produksi Harian | F8: 21:46:43 | H8: DI DALAM | I8: MK00235
A9: 07/03/2026 | B9: 528000360 | C9: Hendra Permana | D9: ENG | E9: Engineering Harian | F9: 21:54:40 | H9: DI DALAM | I9: MK00208 | J9: 8E
A10: 08/03/2026 | B10: 528000040 | C10: Agus Suryaman | D10: PROD | E10: Produksi Harian | F10: 08:51:01 | G10: 22:12:34 | H10: SELESAI | I10: MK00141
A11: 08/03/2026 | B11: 528000052 | C11: Mustopa | D11: PROD | E11: Produksi Harian | G11: 21:04:56 | H11: KELUAR TANPA MASUK | I11: MK00160
A12: 08/03/2026 | B12: 528000090 | C12: Suganda | D12: PROD | E12: Produksi Harian | F12: 13:53:31 | G12: 22:04:42 | H12: SELESAI | I12: MK00250
A13: 08/03/2026 | B13: 528000144 | C13: Jodi Hanafi | D13: LOG | E13: WRM Harian | F13: 15:50:17 | G13: 15:49:57 | H13: SELESAI | I13: MK00221
A14: 08/03/2026 | B14: 528000149 | C14: Tio Fernanda | D14: LOG | E14: WRM Harian | F14: 15:50:30 | H14: DI DALAM | I14: MK0130
A15: 08/03/2026 | B15: 528000201 | C15: Zahwa Amelia Choerunissa | D15: PROD | E15: Produksi Harian | F15: 13:42:00 | G15: 22:04:08 | H15: SELESAI | I15: MK00192
A16: 08/03/2026 | B16: 528000212 | C16: Rizal Fauzi | D16: PROD | E16: Produksi Harian | F16: 14:00:49 | H16: DI DALAM | I16: MK00156
A17: 08/03/2026 | B17: 528000232 | C17: Agung Aji Suhada | D17: LOG | E17: WRM Harian | F17: 08:40:25 | G17: 17:13:43 | H17: SELESAI | I17: MK00150
A18: 08/03/2026 | B18: 528000241 | C18: Balia Nurafif Bilah | D18: PROD | E18: Produksi Harian | F18: 13:54:59 | G18: 22:04:03 | H18: SELESAI | I18: MK00217
A19: 08/03/2026 | B19: 528000261 | C19: Ergi Ergianto | D19: HRGA | E19: GA Harian | G19: 08:04:03 | H19: KELUAR TANPA MASUK | I19: MK00202
A20: 08/03/2026 | B20: 528000262 | C20: Ndari Dwiwanti | D20: PROD | E20: Produksi Harian | G20: 21:46:59 | H20: KELUAR TANPA MASUK | I20: MK00113
A21: 08/03/2026 | B21: 528000265 | C21: Muhammad Haerul Rozikin | D21: LOG | E21: WRM Harian | G21: 16:05:06 | H21: KELUAR TANPA MASUK | I21: MK00154
A22: 08/03/2026 | B22: 528000267 | C22: Bagas Patulloh | D22: LOG | E22: WRM Harian | F22: 08:03:42 | G22: 17:46:36 | H22: SELESAI | I22: MK00093
A23: 08/03/2026 | B23: 528000273 | C23: Asep Mulyana | D23: PROD | E23: Produksi Harian | F23: 13:50:06 | G23: 22:01:43 | H23: SELESAI | I23: MK00116
A24: 08/03/2026 | B24: 528000274 | C24: Zepri | D24: PROD | E24: Produksi Harian | F24: 13:55:07 | G24: 22:03:22 | H24: SELESAI | I24: MK00008
A25: 08/03/2026 | B25: 528000279 | C25: Mahdalena Dalfa Riani | D25: PROD | E25: Produksi Harian | G25: 14:07:32 | H25: KELUAR TANPA MASUK | I25: MK00208
A26: 08/03/2026 | B26: 528000282 | C26: Defa Desfiana | D26: PROD | E26: Produksi Harian | G26: 16:01:50 | H26: KELUAR TANPA MASUK | I26: MK00210 | J26: 32c
A27: 08/03/2026 | B27: 528000286 | C27: Imelda Amelia | D27: PROD | E27: Produksi Harian | F27: 13:43:02 | G27: 22:08:26 | H27: SELESAI | I27: MK00230
A28: 08/03/2026 | B28: 528000289 | C28: Adit Supriyadi | D28: PROD | E28: Produksi Harian | F28: 13:45:13 | H28: DI DALAM | I28: MK00145
A29: 08/03/2026 | B29: 528000290 | C29: Eval Pranata | D29: PROD | E29: Produksi Harian | F29: 13:59:53 | G29: 22:04:49 | H29: SELESAI | I29: MK00109
A30: 08/03/2026 | B30: 528000291 | C30: Andrian | D30: PROD | E30: Produksi Harian | G30: 21:45:50 | H30: KELUAR TANPA MASUK | I30: MK00082
A31: 08/03/2026 | B31: 528000300 | C31: Lia pitaloka | D31: PROD | E31: Produksi Harian | G31: 14:06:53 | H31: KELUAR TANPA MASUK | I31: MK00138
A32: 08/03/2026 | B32: 528000310 | C32: Fachrul Rozzi Suryana | D32: LOG | E32: WRM Harian | F32: 07:54:31 | G32: 16:04:00 | H32: SELESAI | I32: MK00181 | J32: 33E
A33: 08/03/2026 | B33: 528000335 | C33: Rizal Saepuloh | D33: LOG | E33: WRM Harian | F33: 16:03:11 | H33: DI DALAM | I33: MK00204
A34: 08/03/2026 | B34: 528000337 | C34: Ahmad Zaldi Firdaus | D34: PROD | E34: Produksi Harian | F34: 20:49:51 | H34: DI DALAM | I34: MK00209
A35: 08/03/2026 | B35: 528000339 | C35: Muhamad Ripai'i | D35: HRGA | E35: GA Harian | F35: 13:42:41 | G35: 22:40:20 | H35: SELESAI | I35: MK00136
A36: 08/03/2026 | B36: 528000348 | C36: Saepuloh Ardiansah | D36: LOG | E36: WRM Harian | F36: 08:55:10 | G36: 22:11:19 | H36: SELESAI | I36: MK00205
A37: 08/03/2026 | B37: 528000349 | C37: Anas Abdul Fatah | D37: LOG | E37: WFG Harian | F37: 09:47:06 | G37: 18:16:40 | H37: SELESAI | I37: MK00185
A38: 08/03/2026 | B38: 528000351 | C38: Mulyana | D38: PROD | E38: Produksi Harian | F38: 07:51:45 | G38: 16:03:06 | H38: SELESAI | I38: MK00209
A39: 08/03/2026 | B39: 528000358 | C39: Lulu Agustin | D39: PROD | E39: Produksi Harian | G39: 08:05:13 | H39: KELUAR TANPA MASUK | I39: MK00213
A40: 08/03/2026 | B40: 628000064 | C40: Silva Alypia | D40: PROD | E40: Produksi Borongan | G40: 14:05:15 | H40: KELUAR TANPA MASUK | I40: MK00108
...

Sheet REGISTRASI MASUK KELUAR AREA KE
A1: NO KARTU MK | B1: INOUT | C1: TANGGAL | D1: JAM CATAT | E1: NIK | F1: NAMA | G1: TUJUAN | H1: CATATAN
G2: TOILET
G3: ISTRIHAHAT
G4: SHOLAT
G5: KLINIK
A6: MK00160 | B6: IN | C6: 46166.417 | D6: 0.71859954 | E6: 628000039 | F6: Nani Maryani | G6: HRD & GA
A7: MK00160 | B7: OUT | C7: 46166.417 | D7: 0.71930556 | E7: 628000039 | F7: Nani Maryani | G7: HRD & GA
A8: MK00160 | B8: IN | C8: 46166.417 | D8: 0.71960648 | E8: 628000039 | F8: Nani Maryani | G8: HRD & GA | H8: Toilet
A9: MK00112 | B9: IN | C9: 46170.417 | D9: 0.59342593 | E9: 528000016 | F9: Randi Apriyanto | G9: LOG
A10: MK00154 | B10: IN | C10: 46196.417 | D10: 0.63871528 | E10: 528000290 | F10: Eval Pranata | G10: Produksi | H10: Istirahat
A11: MK00154 | B11: OUT | C11: 46196.417 | D11: 0.63952546 | E11: 528000290 | F11: Eval Pranata | G11: Produksi | H11: Pekerjaan
A12: MK00154 | B12: IN | C12: 46196.417 | D12: 0.64038194 | E12: 528000290 | F12: Eval Pranata | G12: Produksi | H12: Pekerjaan
A13: MK00154 | B13: OUT | C13: 46196.417 | D13: 0.64390046 | E13: 528000290 | F13: Eval Pranata | G13: Produksi | H13: Toilet
A14: MK00154 | B14: IN | C14: 46196.417 | D14: 0.6446412 | E14: 528000290 | F14: Eval Pranata | G14: Produksi | H14: Pekerjaan
A15: MK00154 | B15: OUT | C15: 46196.417 | D15: 0.67167824 | E15: 528000290 | F15: Eval Pranata | G15: Produksi | H15: Sholat
A16: 428000104 | B16: IN | C16: 46196.417 | D16: 0.67827546 | E16: 428000104 | F16: BELLA NURLAILLA. AP | G16: Produksi
A17: MK00154 | B17: IN | C17: 46196.417 | D17: 0.68052083 | E17: 528000290 | F17: Eval Pranata | G17: Produksi | H17: Pekerjaan
A18: MK00154 | B18: OUT | C18: 46196.417 | D18: 0.69427083 | E18: 528000290 | F18: Eval Pranata | G18: Produksi | H18: Istirahat
A19: MK00150 | B19: IN | C19: 46196.417 | D19: 0.70960648 | E19: 528000241 | F19: Balia Nurafif Bilah | G19: Produksi | H19: Istirahat
A20: MK00150 | B20: OUT | C20: 46196.417 | D20: 0.71211806 | E20: 528000241 | F20: Balia Nurafif Bilah | G20: Produksi | H20: Istirahat
A21: MK00154 | B21: IN | C21: 46196.417 | D21: 0.71565972 | E21: 528000290 | F21: Eval Pranata | G21: Produksi | H21: Pekerjaan
A22: MK00150 | B22: IN | C22: 46196.417 | D22: 0.73483796 | E22: 528000241 | F22: Balia Nurafif Bilah | G22: Produksi | H22: Pekerjaan
A23: MK00192 | B23: IN | C23: 46196.417 | D23: 0.77207176 | E23: 528000099 | F23: Siti Nurawaliah | G23: Produksi | H23: Istirahat
A24: MK00192 | B24: OUT | C24: 46196.417 | D24: 0.77234954 | E24: 528000099 | F24: Siti Nurawaliah | G24: Produksi | H24: Istirahat
A25: MK00154 | B25: OUT | C25: 46196.417 | D25: 0.77336806 | E25: 528000290 | F25: Eval Pranata | G25: Produksi | H25: Sholat
A26: MK00154 | B26: IN | C26: 46196.417 | D26: 0.78018519 | E26: 528000290 | F26: Eval Pranata | G26: Produksi | H26: Pekerjaan
A27: MK00203 | B27: IN | C27: 46196.417 | D27: 0.78725694 | E27: 528000286 | F27: Imelda Amelia | G27: Produksi | H27: Istirahat
A28: MK00203 | B28: OUT | C28: 46196.417 | D28: 0.78743056 | E28: 528000286 | F28: Imelda Amelia | G28: Produksi | H28: Istirahat
... A73: MK00126 | B73: OUT | C73: 46197.417 | D73: 0.44258102 | E73: 528000254 | F73: M. Difa Ramdani | G73: Produksi | H73: Istirahat
A74: MK00126 | B74: IN | C74: 46197.417 | D74: 0.46815972 | E74: 528000254 | F74: M. Difa Ramdani | G74: Produksi
A75: MK00141 | B75: OUT | C75: 46197.417 | D75: 0.48946759 | E75: 528000265 | F75: Muhammad Haerul Rozikin | G75: Produksi
A76: MK00208 | B76: OUT | C76: 46197.417 | D76: 0.50460648 | E76: 528000282 | F76: Defa Desfiana | G76: Produksi
A77: MK00126 | B77: OUT | C77: 46197.417 | D77: 0.52984954 | E77: 528000254 | F77: M. Difa Ramdani | G77: Produksi
A78: MK00158 | B78: IN | C78: 46197.417 | D78: 0.53157407 | E78: 628000064 | F78: Silva Alypia | G78: Produksi
A79: MK00158 | B79: OUT | C79: 46197.417 | D79: 0.53180556 | E79: 628000064 | F79: Silva Alypia | G79: Produksi | H79: Sholat
A80: MK00230 | B80: IN | C80: 46197.417 | D80: 0.53221065 | E80: 528000279 | F80: Mahdalena Dalfa Riani | G80: Produksi | H80: Sholat
A81: MK00230 | B81: OUT | C81: 46197.417 | D81: 0.53240741 | E81: 528000279 | F81: Mahdalena Dalfa Riani | G81: Produksi | H81: Sholat
A82: MK00126 | B82: IN | C82: 46197.417 | D82: 0.53696759 | E82: 528000254 | F82: M. Difa Ramdani | G82: Produksi | H82: Sholat
A83: MK00230 | B83: IN | C83: 46197.417 | D83: 0.53890046 | E83: 528000279 | F83: Mahdalena Dalfa Riani | G83: Produksi | H83: Sholat
A84: MK00158 | B84: IN | C84: 46197.417 | D84: 0.53924769 | E84: 628000064 | F84: Silva Alypia | G84: Produksi | H84: Sholat
...

Sheet Sheet9
A1: NO | B1: NIK | C1: NAMA | D1: DEPARTMENT | E1: SECTION | F1: GROUP
A2: =IFERROR(__xludf.DUMMYFUNCTION("QUERY('NON STAFF'!A$2:E1000,""select Col1,Col2,Col3,Col6,Col7,Col10 where Col6='Production'"",0) "),"#VALUE!")

Sheet LOG
A1: Jumlah Karyawan Department Logistic
A2: 2024
A3: Section | B3: January | C3: February | D3: March | E3: April | F3: May | G3: June | H3: July | I3: August | J3: September | K3: October | L3: November | M3: December | N3: HF1 | O3: HF2
A4: WFG | B4: 6 | C4: 6 | D4: 7 | E4: 9 | F4: 9 | G4: 11 | H4: 12 | I4: 10 | J4: 10 | K4: 10 | L4: 11 | M4: 11 | N4: =SUM(B4:G4) | O4: =SUM(H4:M4) | P4: =O4-N4
A5: WRM | B5: 11 | C5: 11 | D5: 12 | E5: 11 | F5: 11 | G5: 11 | H5: 11 | I5: 12 | J5: 11 | K5: 12 | L5: 10 | M5: 11 | N5: =SUM(B5:G5) | O5: =SUM(H5:M5) | P5: =O5-N5
A6: EXPEDISI | B6: 1 | C6: 2 | D6: 3 | E6: 2 | F6: 2 | G6: 1 | H6: 1 | I6: 1 | J6: 1 | K6: 1 | L6: 1 | M6: 1 | N6: =SUM(B6:G6) | O6: =SUM(H6:M6) | P6: =O6-N6
A7: TIMBANGAN | G7: 1 | H7: 2 | I7: 2 | J7: 2 | K7: 2 | L7: 2 | M7: 2 | N7: =SUM(B7:G7) | O7: =SUM(H7:M7) | P7: =O7-N7
A8: TOTAL | B8: =SUM(B4:B7) | C8: =SUM(C4:C7) | D8: =SUM(D4:D7) | E8: =SUM(E4:E7) | F8: =SUM(F4:F7) | G8: =SUM(G4:G7) | H8: =SUM(H4:H7) | I8: =SUM(I4:I7) | ... M8: =SUM(M4:M7) | N8: =SUM(B8:G8) | O8: =SUM(H8:M8) | P8: =O8-N8
A10: 2025
A11: Section | B11: January | C11: February | D11: March | E11: April | F11: May | G11: June | H11: July | I11: August | J11: September | K11: October | L11: November | M11: December | N11: HF1 | O11: HF2
A12: WFG | B12: 12 | C12: 11 | D12: 12 | E12: 11 | F12: 11 | G12: 12 | H12: 13 | I12: 13 | J12: 13 | K12: 14 | L12: 13 | M12: 15 | N12: =SUM(B12:G12) | O12: =SUM(H12:M12) | P12: =O12-N12
A13: WRM | B13: 11 | C13: 10 | D13: 9 | E13: 10 | F13: 10 | G13: 10 | H13: 10 | I13: 12 | J13: 11 | K13: 13 | L13: 14 | M13: 13 | N13: =SUM(B13:G13) | O13: =SUM(H13:M13) | P13: =O13-N13
A14: EXPEDISI | B14: 1 | C14: 1 | D14: 1 | E14: 1 | F14: 1 | G14: 2 | H14: 2 | I14: 2 | J14: 2 | K14: 3 | L14: 2 | M14: 2 | N14: =SUM(B14:G14) | O14: =SUM(H14:M14) | P14: =O14-N14
A15: TIMBANGAN | B15: 2 | C15: 2 | D15: 2 | E15: 2 | F15: 2 | G15: 2 | H15: 3 | I15: 3 | J15: 2 | K15: 2 | L15: 2 | M15: 2 | N15: =SUM(B15:G15) | O15: =SUM(H15:M15) | P15: =O15-N15
A16: WSP | H16: 4 | I16: 4 | J16: 4 | K16: 4 | L16: 4 | M16: 4 | N16: =SUM(B16:G16) | O16: =SUM(H16:M16) | P16: =O16-N16
A17: TOTAL | B17: =SUM(B12:B16) | C17: =SUM(C12:C16) | D17: =SUM(D12:D16) | E17: =SUM(E12:E16) | F17: =SUM(F12:F16) | G17: =SUM(G12:G16) | H17: =SUM(H12:H16) | I17: =SUM(I12:I16) | ... M17: =SUM(M12:M16) | N17: =SUM(B17:G17) | O17: =SUM(H17:M17) | P17: =O17-N17
A20: 2026
A21: Section | B21: January | C21: February | D21: March | E21: April | F21: May | G21: June | H21: July | I21: August | J21: September | K21: October | L21: November | M21: December
A22: WFG | B22: 17 | C22: 16
A23: WRM | B23: 12 | C23: 12
A24: EXPEDISI | B24: 2 | C24: 2
A25: TIMBANGAN | B25: 2 | C25: 3
A26: WSP | B26: 4 | C26: 4
A27: TOTAL | B27: =SUM(B22:B26) | C27: =SUM(C22:C26) | D27: =SUM(D22:D26) | E27: =SUM(E22:E26) | F27: =SUM(F22:F26) | G27: =SUM(G22:G26) | H27: =SUM(H22:H26) | I27: =SUM(I22:I26) | ... M27: =SUM(M22:M26)
A66: WRM 2025 | B66: January | C66: February | D66: March | E66: April | F66: May | G66: June | H66: July | I66: August | J66: September | K66: October | L66: November | M66: December
A67: Jumlah Orang | B67: 11 | C67: 10 | D67: 9 | E67: 10 | F67: 10 | G67: 10 | H67: 10 | I67: 12 | J67: 12 | K67: 12 | L67: 12 | M67: 12
A68: Total Box | B68: 644953 | C68: 568481 | D68: 631846 | E68: 569922 | F68: 624962 | G68: 656671 | H68: 728771 | I68: 717211 | J68: 246867 | K68: 0 | L68: 0 | M68: 0
A69: Baby (Box) | B69: 644953 | C69: 568481 | D69: 631846 | E69: 569922 | F69: 624962 | G69: 645173 | H69: 644284 | I69: 632555 | J69: 213691 | K69: 0 | L69: 0 | M69: 0
A70: Adult (Box) | B70: 0 | C70: 0 | D70: 0 | E70: 0 | F70: 0 | G70: 11498 | H70: 84487 | I70: 84656 | J70: 33176 | K70: 0 | L70: 0 | M70: 0
A71: Total Pallet | B71: 14985 | C71: 13350 | D71: 13945 | E71: 13588 | F71: 14604 | G71: 15322 | H71: 17583 | I71: 18047 | J71: 6512 | K71: 0 | L71: 0 | M71: 0
A72: Baby (Pallet) | B72: 14985 | C72: 13350 | D72: 13945 | E72: 13588 | F72: 14604 | G72: 14946 | H72: 14740 | I72: 14709 | J72: 5229 | K72: 0 | L72: 0 | M72: 0
A73: Adult (Pallet) | B73: 0 | C73: 0 | D73: 0 | E73: 0 | F73: 0 | G73: 376 | H73: 2844 | I73: 3338 | J73: 1283 | K73: 0 | L73: 0 | M73: 0
A74: Box per man | B74: =B68/B67 | C74: =C68/C67 | D74: =D68/D67 | E74: =E68/E67 | F74: =F68/F67 | G74: =G68/G67 | H74: =H68/H67 | I74: =I68/I67 | ... M74: =M68/M67
A75: Pallet per man | B75: =B71/B67 | C75: =C71/C67 | D75: =D71/D67 | E75: =E71/E67 | F75: =F71/F67 | G75: =G71/G67 | H75: =H71/H67 | I75: =I71/I67 | ... M75: =M71/M67
B76: =B75/25 | C76: =C75/25 | D76: =D75/25 | E76: =E75/25 | F76: =F75/25 | G76: =G75/25 | H76: =H75/25 | I76: =I75/25 | ... M76: =M75/25
A78: WFG 2025 | B78: January | C78: February | D78: March | E78: April | F78: May | G78: June | H78: July | I78: August | J78: September | K78: October | L78: November | M78: December
A79: Jumlah Orang | B79: 12 | C79: 11 | D79: 12 | E79: 11 | F79: 11 | G79: 12 | H79: 13 | I79: 13 | J79: 13 | K79: 13 | L79: 13 | M79: 13
A80: Total Box
A81: Baby (Box)
A82: Adult (Box)
...

Sheet PROD
A1: Jumlah Karyawan Department PROD
A2: 2024
A3: Section | B3: January | C3: February | D3: March | E3: April | F3: May | G3: June | H3: July | I3: August | J3: September | K3: October | L3: November | M3: December
A4: BHP | B4: 141 | C4: 140 | D4: 140 | E4: 138 | F4: 140 | G4: 141 | H4: 142 | I4: 140 | J4: 141 | K4: 146 | L4: 140 | M4: 139
A5: HPY
A6: TOTAL | B6: =SUM(B4:B5) | C6: =SUM(C4:C5) | D6: =SUM(D4:D5) | E6: =SUM(E4:E5) | F6: =SUM(F4:F5) | G6: =SUM(G4:G5) | H6: =SUM(H4:H5) | I6: =SUM(I4:I5) | ... M6: =SUM(M4:M5)
A8: 2025
A9: Section | B9: January | C9: February | D9: March | E9: April | F9: May | G9: June | H9: July | I9: August | J9: September | K9: October | L9: November | M9: December
A10: BHP | B10: 139 | C10: 138 | D10: 136 | E10: 139 | F10: 152 | G10: 135 | H10: 139 | I10: 139 | J10: 133 | K10: 137 | L10: 133 | M10: 147
A11: HPY | G11: 29 | H11: 34 | I11: 36 | J11: 43 | K11: 43 | L11: 41 | M11: 51
A12: TOTAL | B12: =SUM(B10:B11) | C12: =SUM(C10:C11) | D12: =SUM(D10:D11) | E12: =SUM(E10:E11) | F12: =SUM(F10:F11) | G12: =SUM(G10:G11) | H12: =SUM(H10:H11) | I12: =SUM(I10:I11) | ... M12: =SUM(M10:M11)
A14: 2026
A15: Section | B15: January | C15: February | D15: March | E15: April | F15: May | G15: June | H15: July | I15: August | J15: September | K15: October | L15: November | M15: December
A16: BHP | B16: 152 | C16: 191
A17: HPY | B17: 45 | C17: 45
A18: TOTAL | B18: =SUM(B16:B17) | C18: =SUM(C16:C17) | D18: =SUM(D16:D17) | E18: =SUM(E16:E17) | F18: =SUM(F16:F17) | G18: =SUM(G16:G17) | H18: =SUM(H16:H17) | I18: =SUM(I16:I17) | ... M18: =SUM(M16:M17)

Sheet STAFF PROD DES 24
A1: DATA STAFF AKTIF PER DESEMBER 24 - PT DAM
A3: NO | B3: NIK | C3: Nama | D3: CC | E3: Dept | F3: JABATAN
A4: 1 | B4: 128000001 | C4: Iman Nurchaedi S. | D4: 111102 | E4: Production | F4: Plant Manager
A5: 2 | B5: 128000010 | C5: Dendy Saputra | D5: 111102 | E5: Production | F5: Line Leader
A6: 3 | B6: 128000012 | C6: Evita | D6: 111102 | E6: Production | F6: Production Chief SPV 1
A7: 4 | B7: 128000022 | C7: Hendra Setiawan | D7: 111102 | E7: Production | F7: Production Engineer
A8: 5 | B8: 128000029 | C8: Angga Setyawan | D8: 111102 | E8: Production | F8: Shift Leader
A9: 6 | B9: 128000030 | C9: Kelik Aji Sambudi | D9: 111102 | E9: Production | F9: Shift Leader
A10: 7 | B10: 128000031 | C10: Abdu Fuad Arrazy | D10: 111102 | E10: Production | F10: Shift Leader
A11: 8 | B11: 128000039 | C11: Saka Marga Redi | D11: 111102 | E11: Production | F11: Line Leader
A12: 9 | B12: 128000040 | C12: Gilang Anugerah Hernanda | D12: 111102 | E12: Production | F12: Line Leader
A13: 10 | B13: 128000041 | C13: Alief Akbar Rafsanzani | D13: 111102 | E13: Production | F13: Shift Leader
A14: 11 | B14: 128000042 | C14: Ahmad Afrizal | D14: 111102 | E14: Production | F14: Line Leader
A15: 12 | B15: 128000070 | C15: Bey Muhammad | D15: 111102 | E15: Production | F15: Line Leader
A16: 13 | B16: 128000071 | C16: Febri Wira Wijaya | D16: 111102 | E16: Production | F16: Line Leader

Sheet STAFF NONPROD DES 24
A1: DATA STAFF AKTIF PER DESEMBER 24 - PT DAM
A3: NO | B3: NIK | C3: Nama | D3: CC | E3: Dept | F3: JABATAN
A4: 1 | B4: 128000003 | C4: Andre Santosa | D4: 121101 | E4: Engineering | F4: Engineering Deputy Manager
A5: 2 | B5: 128000049 | C5: Ragil Febriansyah | D5: 331101 | E5: Engineering | F5: Staff ITE
A6: 3 | B6: 128000027 | C6: Gembong Hagung Harsanto | D6: 121101 | E6: Engineering | F6: Engineering Chief Spv 1
